# SOME DESCRIPTIVE TITLE.
# Copyright (C) YEAR THE PACKAGE'S COPYRIGHT HOLDER
# This file is distributed under the same license as the PACKAGE package.
# FIRST AUTHOR <EMAIL@ADDRESS>, YEAR.
#
msgid ""
msgstr ""
"Project-Id-Version: Django web utils\n"
"Report-Msgid-Bugs-To: \n"
"POT-Creation-Date: 2024-05-23 13:37+0000\n"
"PO-Revision-Date: 2024-05-23 15:42+0200\n"
"Last-Translator: Stéphane Diemer <stephane.diemer@ubicast.eu>\n"
"Language-Team: UbiCast <support@ubicast.eu>\n"
"Language: fr_FR\n"
"MIME-Version: 1.0\n"
"Content-Type: text/plain; charset=UTF-8\n"
"Content-Transfer-Encoding: 8bit\n"
"X-Generator: Poedit 3.2.2\n"

#: admin_utils.py:12
msgid "Export selected objects as CSV file"
msgstr "Exporter les objets sélectionnés dans un fichier CSV"

#: admin_utils.py:110
msgid "CSV export"
msgstr "Export CSV"

#: antivirus_utils.py:47
msgid "Your request was reported and if you send again infected files, you will be banned."
msgstr "Votre requête a été signalée et si vous envoyez à nouveau des fichiers infectés, vous serez banni."

#: antivirus_utils.py:48
msgid "Failed to run antivirus scanner."
msgstr "Échec de l'exécution du scanner antivirus."

#: antivirus_utils.py:49
msgid "Cannot scan file because it does not exist."
msgstr "Impossible d'analyser le fichier car il n'existe pas."

#: antivirus_utils.py:50
msgid "Your file was rejected because it is infected."
msgstr "Votre fichier a été rejeté car il est infecté."

#: antivirus_utils.py:51
msgid "Cannot scan file because it is not a file."
msgstr "Impossible d'analyser le fichier car il ne s'agit pas d'un fichier."

#: antivirus_utils.py:52
msgid "Cannot scan file because it is neither a file nor a directory."
msgstr "Impossible d'analyser le fichier car ce n'est ni un fichier ni un répertoire."

#: antivirus_utils.py:53
msgid "Failed to scan your file with the antivirus."
msgstr "L'analyse de votre fichier par l'antivirus a échoué."

#: auth_utils.py:40
msgid "Your account is disabled."
msgstr "Votre compte est désactivé."

#: auth_utils.py:42
msgid "Your username and password do not match."
msgstr "Votre nom d'utilisateur et votre mot de passe ne correspondent pas."

#: auth_utils.py:44
msgid "Authentication required."
msgstr "Authentification requise."

#: auth_utils.py:47
msgid "Access authentication"
msgstr "Authentification d'accès"

#: auth_utils.py:83 auth_utils.py:88
msgid "The password must contain at least 3 types of characters (types are lower case letters, upper case letters, digits and special characters)."
msgstr "Le mot de passe doit contenir au minimum 3 types de caractères (les types sont : lettres minuscules, lettres majuscules, chiffres et caractères spéciaux)."

#: files_utils.py:48
msgid "B"
msgstr "o"

#: files_utils.py:52
msgid "kB"
msgstr "ko"

#: files_utils.py:56
msgid "MB"
msgstr "Mo"

#: files_utils.py:60
msgid "GB"
msgstr "Go"

#: files_utils.py:63
msgid "TB"
msgstr "To"

#: forms_utils.py:119 settings_store/forms.py:48
msgid "Yes"
msgstr "Oui"

#: forms_utils.py:121 settings_store/forms.py:50
msgid "No"
msgstr "Non"

#: json_utils.py:89
msgid "Invalid request method"
msgstr "Méthode de requête invalide"

#: json_utils.py:94
msgid "Authentication required"
msgstr "Authentification requise"

#: json_utils.py:125
msgid "Access denied"
msgstr "Accès refusé"

#: json_utils.py:127
msgid "Page not found"
msgstr "Page introuvable"

#: json_utils.py:132
msgid "Infected file detected"
msgstr "Fichier infecté détecté"

#: json_utils.py:137
msgid "Internal server error"
msgstr "Erreur interne au serveur"

#: ldap_utils.py:74
msgid "Error when initializing connection with LDAP server."
msgstr "Erreur lors de l'initialisation de la connexion avec le serveur LDAP."

#: ldap_utils.py:74 ldap_utils.py:102 ldap_utils.py:129 ldap_utils.py:280
msgid "Error:"
msgstr "Erreur :"

#: ldap_utils.py:102
msgid "Error when trying to authenticate on LDAP server."
msgstr "Erreur lors de l'authentification sur le serveur LDAP."

#: ldap_utils.py:128
msgid "Search on LDAP server failed."
msgstr "Recherche échouée sur le serveur LDAP."

#: ldap_utils.py:131
msgid "Arguments:"
msgstr "Arguments :"

#: ldap_utils.py:165
msgid "User not found."
msgstr "Utilisateur introuvable."

#: ldap_utils.py:177
msgid "Group not found."
msgstr "Groupe introuvable."

#: ldap_utils.py:280
msgid "Error when trying to get user information."
msgstr "Erreur lors de la récupération des informations de l'utilisateur."

#: ldap_utils.py:289
msgid "Login failed (however the user exists in LDAP)."
msgstr "Échec de l'authentification (l'utilisateur existe bien dans LDAP)."

#: ldap_utils.py:291
msgid "Login succeeded."
msgstr "Authentification réussie."

#: ldap_utils.py:292
#, python-format
msgid "User \"%s\" data:"
msgstr "Données de l'utilisateur \"%s\" :"

#: ldap_utils.py:297
msgid "User groups:"
msgstr "Groupes de l'utilisateur :"

#: ldap_utils.py:302
msgid "Error when trying to get groups."
msgstr "Erreur lors de la récupération des groupes de l'utilisateur."

#: ldap_utils.py:313
msgid "No groups found."
msgstr "Aucun groupe n'a été trouvé."

#: magic_login/forms.py:11
msgid "Email address"
msgstr "Adresse e-mail"

#: magic_login/forms.py:16
msgid "Invalid email address."
msgstr "L'adresse e-mail n'est pas valide."

#: magic_login/views.py:115
msgid "The submitted form is incorrect. Please correct all errors and send it again."
msgstr "Le formulaire saisi est incorrect. Veuillez corriger les erreurs puis le renvoyer."

#: magic_login/views.py:128
msgid "The requested email address is not allowed."
msgstr "L'adresse e-mail demandée n'est pas autorisée."

#: magic_login/views.py:137
#, python-format
msgid "Link to authenticate on %s"
msgstr "Lien pour s'authentifier sur %s"

#: magic_login/views.py:148
msgid "Here is the link to log in on the site:"
msgstr "Voici le lien pour s'authentifier sur le site :"

#: magic_login/views.py:149
msgid "If you did not request this link, ignore this email."
msgstr "Si vous n'avez pas demandé ce lien, ignorez cet e-mail."

#: magic_login/views.py:162
msgid "Failed to send the email:"
msgstr "L'envoi de l'e-mail a échoué :"

#: magic_login/views.py:164
msgid "An email has been sent to you with the link to log in."
msgstr "Un e-mail vous a été envoyé avec le lien pour vous connecter."

#: magic_login/views.py:169
msgid "Your session has expired, please get a new link to retry."
msgstr "Votre session a expiré, veuillez obtenir un nouveau lien pour réessayer."

#: magic_login/views.py:173
msgid "Your request is invalid."
msgstr "Votre requête n'est pas valide."

#: settings_store/forms.py:81 settings_utils.py:64 settings_utils.py:125
msgid "No changes to save."
msgstr "Aucune modification à sauvegarder."

#: settings_store/forms.py:84
msgid "Your changes will be active in a few seconds."
msgstr "Vos modifications seront actives dans quelques secondes."

#: settings_utils.py:69 settings_utils.py:131
#, python-format
msgid "Invalid setting name: %s"
msgstr "Nom de paramètre non valide : %s"

#: settings_utils.py:79 settings_utils.py:141
msgid "Your changes were not saved but were applied to the running software."
msgstr "Vos modifications n'ont pas été sauvegardées mais ont été appliquées à l'application en cours."

#: settings_utils.py:113 settings_utils.py:170
msgid "Unable to write configuration file:"
msgstr "Impossible d'écrire le fichier de configuration :"

#: settings_utils.py:115 settings_utils.py:172
msgid "Your changes have been applied. The service will be reloaded in a few seconds to make them effective."
msgstr "Vos modifications ont été appliquées. Le service sera rechargé dans quelques secondes pour les rendre effectives."

#: system_utils.py:93
msgid "Password required."
msgstr "Mot de passe requis."

#: system_utils.py:102
#, python-format
msgid "Command exited with code %s."
msgstr "La commande a retourné un code %s."

#: system_utils.py:134 system_utils.py:137 system_utils.py:143
#: system_utils.py:163
msgid "Unable to write file."
msgstr "Impossible d'écrire le fichier."

#: system_utils.py:134
msgid "Specified path is a directory."
msgstr "Le chemin spécifié est un dossier."

#: system_utils.py:137
msgid "Invalid file path."
msgstr "Chemin du fichier invalide."

#: system_utils.py:149
msgid "You need to send the main password to edit this file."
msgstr "Vous devez entrer le mot de passe principal pour éditer ce fichier."

#: system_utils.py:157
#, python-format
msgid "Unable to create temporary file \"%s\"."
msgstr "Impossible de créer le fichier temporaire \"%s\"."

#: system_utils.py:164
msgid "File updated."
msgstr "Fichier mis à jour."

#: templates/forms_utils/password_toggle_input.html:5
msgid "Hide value"
msgstr "Cacher la valeur"

#: templates/forms_utils/password_toggle_input.html:5
#: templates/forms_utils/password_toggle_input.html:7
msgid "Edit value"
msgstr "Éditer la valeur"

#~ msgid "Failed to backup settings:"
#~ msgstr "Échec de la création d'un point de sauvegarde des paramètres :"

#~ msgid "Your changes will be active after the service restart."
#~ msgstr "Vos modifications seront actives après le redémarrage du service."

#~ msgid "The service will be restarted in 2 seconds."
#~ msgstr "Le service sera redémarré dans 2 secondes."
