# SOME DESCRIPTIVE TITLE.
# Copyright (C) YEAR THE PACKAGE'S COPYRIGHT HOLDER
# This file is distributed under the same license as the PACKAGE package.
# FIRST AUTHOR <EMAIL@ADDRESS>, YEAR.
#
msgid ""
msgstr ""
"Project-Id-Version: Django web utils\n"
"Report-Msgid-Bugs-To: \n"
"POT-Creation-Date: 2020-10-06 11:12+0200\n"
"PO-Revision-Date: 2020-10-06 11:13+0200\n"
"Last-Translator: Stéphane Diemer <stephane.diemer@ubicast.eu>\n"
"Language-Team: UbiCast <support@ubicast.eu>\n"
"Language: fr_FR\n"
"MIME-Version: 1.0\n"
"Content-Type: text/plain; charset=UTF-8\n"
"Content-Transfer-Encoding: 8bit\n"
"X-Generator: Poedit 2.2.1\n"

#: admin_utils.py:14
msgid "Export selected objects as CSV file"
msgstr "Exporter les objets sélectionnés dans un fichier CSV"

#: admin_utils.py:112
msgid "CSV export"
msgstr "Export CSV"

#: files_utils.py:39
msgid "B"
msgstr "o"

#: files_utils.py:42
msgid "kB"
msgstr "ko"

#: files_utils.py:45
msgid "MB"
msgstr "Mo"

#: files_utils.py:48
msgid "GB"
msgstr "Go"

#: files_utils.py:51
msgid "TB"
msgstr "To"

#: forms_utils.py:103
msgid "Yes"
msgstr "Oui"

#: forms_utils.py:105
msgid "No"
msgstr "Non"

#: json_utils.py:80
msgid "Invalid request method"
msgstr "Méthode de requête invalide"

#: json_utils.py:88
msgid "Authentication required"
msgstr "Authentification requise"

#: json_utils.py:91
msgid "Access denied"
msgstr "Accès refusé"

#: json_utils.py:93
msgid "Page not found"
msgstr "Page introuvable"

#: json_utils.py:97
msgid "Internal server error"
msgstr "Erreur interne au serveur"

#: ldap_utils.py:76
msgid "Error when initializing connection with LDAP server."
msgstr "Erreur lors de l'initialisation de la connexion avec le serveur LDAP."

#: ldap_utils.py:76 ldap_utils.py:104 ldap_utils.py:131 ldap_utils.py:282
msgid "Error:"
msgstr "Erreur :"

#: ldap_utils.py:104
msgid "Error when trying to authenticate on LDAP server."
msgstr "Erreur lors de l'authentification sur le serveur LDAP."

#: ldap_utils.py:130
msgid "Search on LDAP server failed."
msgstr "Recherche échouée sur le serveur LDAP."

#: ldap_utils.py:133
msgid "Arguments:"
msgstr "Arguments :"

#: ldap_utils.py:167
msgid "User not found."
msgstr "Utilisateur introuvable."

#: ldap_utils.py:179
msgid "Group not found."
msgstr "Groupe introuvable."

#: ldap_utils.py:282
msgid "Error when trying to get user information."
msgstr "Erreur lors de la récupération des informations de l'utilisateur."

#: ldap_utils.py:291
msgid "Login failed (however the user exists in LDAP)."
msgstr "Échec de l'authentification (l'utilisateur existe bien dans LDAP)."

#: ldap_utils.py:293
msgid "Login succeeded."
msgstr "Authentification réussie."

#: ldap_utils.py:294
#, python-format
msgid "User \"%s\" data:"
msgstr "Données de l'utilisateur \"%s\" :"

#: ldap_utils.py:299
msgid "User groups:"
msgstr "Groupes de l'utilisateur :"

#: ldap_utils.py:304
msgid "Error when trying to get groups."
msgstr "Erreur lors de la récupération des groupes de l'utilisateur."

#: ldap_utils.py:315
msgid "No groups found."
msgstr "Aucun groupe n'a été trouvé."

#: settings_utils.py:35
msgid "Failed to backup settings:"
msgstr "Échec de la création d'un point de sauvegarde des paramètres :"

#: settings_utils.py:42
msgid "No changes to save."
msgstr "Aucune modification a sauvegarder."

#: settings_utils.py:89 settings_utils.py:132
msgid "Unable to write configuration file:"
msgstr "Impossible d'écrire le fichier de configuration :"

#: settings_utils.py:90 settings_utils.py:133
msgid "Your changes will be active after the service restart."
msgstr "Vos modifications seront actives après le redémarrage du service."

#: settings_utils.py:95 settings_utils.py:137
msgid "Warning:"
msgstr "Attention :"

#: settings_utils.py:150
msgid "No restart because service is in debug mode."
msgstr "Aucun redémarrage n'est effectué lorsque le service est en mode debug."

#: settings_utils.py:155
msgid "No function defined to restart the service."
msgstr "Aucune fonction n'est définie pour redémarrer le service."

#: settings_utils.py:161
msgid "Failed to restart the service:"
msgstr "Échec du redémarrage du service :"

#: system_utils.py:99
msgid "Password required."
msgstr "Mot de passe requis."

#: system_utils.py:108
#, python-format
msgid "Command exited with code %s."
msgstr "La commande a retourné un code %s."

#: system_utils.py:139 system_utils.py:141 system_utils.py:148
#: system_utils.py:169
msgid "Unable to write file."
msgstr "Impossible d'écrire le fichier."

#: system_utils.py:139
msgid "Specified path is a directory."
msgstr "Le chemin spécifié est un dossier."

#: system_utils.py:141
msgid "Invalid file path."
msgstr "Chemin du fichier invalide."

#: system_utils.py:154
msgid "You need to send the main password to edit this file."
msgstr "Vous devez entrer le mot de passe principal pour éditer ce fichier."

#: system_utils.py:163
#, python-format
msgid "Unable to create temporary file \"%s\"."
msgstr "Impossible de créer le fichier temporaire \"%s\"."

#: system_utils.py:170
msgid "File updated."
msgstr "Fichier mis à jour."
