# SOME DESCRIPTIVE TITLE.
# Copyright (C) YEAR THE PACKAGE'S COPYRIGHT HOLDER
# This file is distributed under the same license as the PACKAGE package.
# FIRST AUTHOR <EMAIL@ADDRESS>, YEAR.
#
msgid ""
msgstr ""
"Project-Id-Version: Django web utils\n"
"Report-Msgid-Bugs-To: \n"
"POT-Creation-Date: 2022-07-11 06:46+0000\n"
"PO-Revision-Date: 2022-07-11 08:37+0200\n"
"Last-Translator: Stéphane Diemer <stephane.diemer@ubicast.eu>\n"
"Language-Team: UbiCast <support@ubicast.eu>\n"
"Language: fr_FR\n"
"MIME-Version: 1.0\n"
"Content-Type: text/plain; charset=UTF-8\n"
"Content-Transfer-Encoding: 8bit\n"
"X-Generator: Poedit 2.4.2\n"

#: admin_utils.py:14
msgid "Export selected objects as CSV file"
msgstr "Exporter les objets sélectionnés dans un fichier CSV"

#: admin_utils.py:112
msgid "CSV export"
msgstr "Export CSV"

#: antivirus_utils.py:49
msgid "Your request was reported and if you send again infected files, you will be banned."
msgstr "Votre requête a été signalée et si vous envoyez à nouveau des fichiers infectés, vous serez banni."

#: antivirus_utils.py:50
msgid "Failed to run antivirus scanner."
msgstr "Échec de l'exécution du scanner antivirus."

#: antivirus_utils.py:51
msgid "Cannot scan file because it does not exist."
msgstr "Impossible d'analyser le fichier car il n'existe pas."

#: antivirus_utils.py:52
msgid "Your file was rejected because it is infected."
msgstr "Votre fichier a été rejeté car il est infecté."

#: antivirus_utils.py:53
msgid "Cannot scan file because it is not a file."
msgstr "Impossible d'analyser le fichier car il ne s'agit pas d'un fichier."

#: antivirus_utils.py:54
msgid "Cannot scan file because it is neither a file nor a directory."
msgstr "Impossible d'analyser le fichier car ce n'est ni un fichier ni un répertoire."

#: antivirus_utils.py:55
msgid "Failed to scan your file with the antivirus."
msgstr "L'analyse de votre fichier par l'antivirus a échoué."

#: auth_utils.py:42
msgid "Your account is disabled."
msgstr "Votre compte est désactivé."

#: auth_utils.py:44
msgid "Your username and password do not match."
msgstr "Votre nom d'utilisateur et votre mot de passe ne correspondent pas."

#: auth_utils.py:46
msgid "Authentication required."
msgstr "Authentification requise."

#: auth_utils.py:49
msgid "Access authentication"
msgstr "Authentification d'accès"

#: auth_utils.py:85 auth_utils.py:90
msgid "The password must contain at least 3 types of characters (types are lower case letters, upper case letters, digits and special characters)."
msgstr "Le mot de passe doit contenir au minimum 3 types de caractères (les types sont : lettres minuscules, lettres majuscules, chiffres et caractères spéciaux)."

#: files_utils.py:40
msgid "B"
msgstr "o"

#: files_utils.py:44
msgid "kB"
msgstr "ko"

#: files_utils.py:48
msgid "MB"
msgstr "Mo"

#: files_utils.py:52
msgid "GB"
msgstr "Go"

#: files_utils.py:55
msgid "TB"
msgstr "To"

#: forms_utils.py:121 settings_store/forms.py:48
msgid "Yes"
msgstr "Oui"

#: forms_utils.py:123 settings_store/forms.py:50
msgid "No"
msgstr "Non"

#: json_utils.py:91
msgid "Invalid request method"
msgstr "Méthode de requête invalide"

#: json_utils.py:96
msgid "Authentication required"
msgstr "Authentification requise"

#: json_utils.py:127
msgid "Access denied"
msgstr "Accès refusé"

#: json_utils.py:129
msgid "Page not found"
msgstr "Page introuvable"

#: json_utils.py:134
msgid "Infected file detected"
msgstr "Fichier infecté détecté"

#: json_utils.py:139
msgid "Internal server error"
msgstr "Erreur interne au serveur"

#: ldap_utils.py:76
msgid "Error when initializing connection with LDAP server."
msgstr "Erreur lors de l'initialisation de la connexion avec le serveur LDAP."

#: ldap_utils.py:76 ldap_utils.py:104 ldap_utils.py:131 ldap_utils.py:282
msgid "Error:"
msgstr "Erreur :"

#: ldap_utils.py:104
msgid "Error when trying to authenticate on LDAP server."
msgstr "Erreur lors de l'authentification sur le serveur LDAP."

#: ldap_utils.py:130
msgid "Search on LDAP server failed."
msgstr "Recherche échouée sur le serveur LDAP."

#: ldap_utils.py:133
msgid "Arguments:"
msgstr "Arguments :"

#: ldap_utils.py:167
msgid "User not found."
msgstr "Utilisateur introuvable."

#: ldap_utils.py:179
msgid "Group not found."
msgstr "Groupe introuvable."

#: ldap_utils.py:282
msgid "Error when trying to get user information."
msgstr "Erreur lors de la récupération des informations de l'utilisateur."

#: ldap_utils.py:291
msgid "Login failed (however the user exists in LDAP)."
msgstr "Échec de l'authentification (l'utilisateur existe bien dans LDAP)."

#: ldap_utils.py:293
msgid "Login succeeded."
msgstr "Authentification réussie."

#: ldap_utils.py:294
#, python-format
msgid "User \"%s\" data:"
msgstr "Données de l'utilisateur \"%s\" :"

#: ldap_utils.py:299
msgid "User groups:"
msgstr "Groupes de l'utilisateur :"

#: ldap_utils.py:304
msgid "Error when trying to get groups."
msgstr "Erreur lors de la récupération des groupes de l'utilisateur."

#: ldap_utils.py:315
msgid "No groups found."
msgstr "Aucun groupe n'a été trouvé."

#: settings_store/forms.py:81 settings_utils.py:74
msgid "No changes to save."
msgstr "Aucune modification a sauvegarder."

#: settings_store/forms.py:84
msgid "Your changes will be active in a few seconds."
msgstr "Vos modifications seront actives dans quelques secondes."

#: settings_utils.py:36
msgid "Failed to backup settings:"
msgstr "Échec de la création d'un point de sauvegarde des paramètres :"

#: settings_utils.py:83 settings_utils.py:143
msgid "Your changes were not saved but were applied to the running software."
msgstr "Vos modifications n'ont pas été sauvegardées mais ont été appliquées à l'application en cours."

#: settings_utils.py:120 settings_utils.py:172
msgid "Unable to write configuration file:"
msgstr "Impossible d'écrire le fichier de configuration :"

#: settings_utils.py:121 settings_utils.py:173
msgid "Your changes will be active after the service restart."
msgstr "Vos modifications seront actives après le redémarrage du service."

#: settings_utils.py:123 settings_utils.py:175
msgid "The service will be restarted in 2 seconds."
msgstr "Le service sera redémarré dans 2 secondes."

#: system_utils.py:99
msgid "Password required."
msgstr "Mot de passe requis."

#: system_utils.py:108
#, python-format
msgid "Command exited with code %s."
msgstr "La commande a retourné un code %s."

#: system_utils.py:139 system_utils.py:141 system_utils.py:148
#: system_utils.py:169
msgid "Unable to write file."
msgstr "Impossible d'écrire le fichier."

#: system_utils.py:139
msgid "Specified path is a directory."
msgstr "Le chemin spécifié est un dossier."

#: system_utils.py:141
msgid "Invalid file path."
msgstr "Chemin du fichier invalide."

#: system_utils.py:154
msgid "You need to send the main password to edit this file."
msgstr "Vous devez entrer le mot de passe principal pour éditer ce fichier."

#: system_utils.py:163
#, python-format
msgid "Unable to create temporary file \"%s\"."
msgstr "Impossible de créer le fichier temporaire \"%s\"."

#: system_utils.py:170
msgid "File updated."
msgstr "Fichier mis à jour."

#: templates/forms_utils/password_toggle_input.html:5
msgid "Hide value"
msgstr "Cacher la valeur"

#: templates/forms_utils/password_toggle_input.html:5
#: templates/forms_utils/password_toggle_input.html:7
msgid "Edit value"
msgstr "Éditer la valeur"
